Workbook

Sheet Wali Kelas
A2: No | B2: Kelas | C2: JML Santri | D2: Wali Kelas | E2: Nik Wali kelas
A3: 1 | B3: 7-A-01 | C3: 30 | D3: Ahrom Hidayat, S.Pd.I. | E3: GR1700604
A4: 2 | B4: 7-A-02 | C4: 30 | D4: Lahmudin, S.E. | E4: GR1700615
A5: 3 | B5: 7-A-03 | C5: 30 | D5: Adi Muhlasin, S.Pd.I. | E5: GR1700600
A6: 4 | B6: 7-A-04 | C6: 28 | D6: Bambang Supriadi, S.Pd.I. | E6: GR1700606
A7: 5 | B7: 7-A-05 | C7: 28 | D7: Wicaksana Sudarma, S.Pd.I. | E7: GR1700628
A8: 6 | B8: 7-A-06 | C8: 28 | D8: A. Rauf, S.Sos.I. | E8: GR1700598
A9: 7 | B9: 7-A-07 | C9: 28 | D9: Suparyono, S.Pd.I. | E9: GR1700625
A10: 8 | B10: 7-B-01 | C10: 26 | D10: Umi Sepriati, S.Ag., M.A.P. | E10: GR0600444
A11: 9 | B11: 7-B-02 | C11: 26 | D11: Eti, S.Ag. | E11: GR0600017
A12: 10 | B12: 7-B-03 | C12: 26 | D12: Titik Listiana, S.S. | E12: GR1700627
A13: 11 | B13: 7-B-04 | C13: 26 | D13: Khonis Muizah, S.Pd.I. | E13: GR1700614
A14: 12 | B14: 7-B-05 | C14: 26 | D14: Leni Marlina, S.Pi. | E14: GR1700616
... A52: 50 | B52: 9-B-09 | C52: 27 | D52: Anna Yunia, S.Pd. | E52: GR1800665

Sheet Data Foto
A1: No. | B1: No. Urut | C1: No. Induk | D1: NISN | F1: L/P | G1: Kelas | H1: Kamar | I1: Level | J1: Koordinator | K1: Sudah Foto atau belum | L1: Ket
A2: 1 | B2: 1 | C2: 20220203 | D2: 0108846340 | E2: Ahmad Rezky Ardiansyah bin Rofikhul Hadi | F2: L | G2: 9-A-01 | H2: 309 MD | I2: 9 | J2: Jakarta Selatan | K2: =IFERROR(INDEX('Data Real Foto'!B:B,MATCH('Data Foto'!C2,'Data Real Foto'!A:A,0)),"") -> Sudah Foto
A3: 2 | B3: 2 | C3: 20220339 | D3: 3101182733 | E3: Akhmad Tegar Fatahillah bin M. Agus Riyadi | F3: L | G3: 9-A-01 | H3: 218 MD | I3: 9 | J3: Jakarta Timur | K3: =IFERROR(INDEX('Data Real Foto'!B:B,MATCH('Data Foto'!C3,'Data Real Foto'!A:A,0)),"") -> Sudah Foto
A4: 3 | B4: 3 | C4: 20220373 | D4: 3101367159 | E4: Al Frinsa Pratama As Shodiqin bin Yatno | F4: L | G4: 9-A-01 | H4: 328 MD | I4: 9 | J4: Jakarta Timur | K4: =IFERROR(INDEX('Data Real Foto'!B:B,MATCH('Data Foto'!C4,'Data Real Foto'!A:A,0)),"") -> Sudah Foto
A5: 4 | B5: 4 | C5: 20220510 | D5: 3091049651 | E5: Aldin Hanif bin Dede Ramdani | F5: L | G5: 9-A-01 | H5: 214 MD | I5: 9 | J5: Jawa Barat Selatan | K5: =IFERROR(INDEX('Data Real Foto'!B:B,MATCH('Data Foto'!C5,'Data Real Foto'!A:A,0)),"") -> Sudah Foto
A6: 5 | B6: 5 | C6: 20220027 | D6: 3092527154 | E6: Alfian Muhammad Nabil bin Mardonal | F6: L | G6: 9-A-01 | H6: 311 MD | I6: 9 | J6: Pusat | K6: =IFERROR(INDEX('Data Real Foto'!B:B,MATCH('Data Foto'!C6,'Data Real Foto'!A:A,0)),"") -> Sudah Foto
A7: 6 | B7: 6 | C7: 20220015 | D7: 3097625940 | E7: Bagus Tri Ramadan bin Sariman | F7: L | G7: 9-A-01 | H7: 317 MD | I7: 9 | J7: Pusat | K7: =IFERROR(INDEX('Data Real Foto'!B:B,MATCH('Data Foto'!C7,'Data Real Foto'!A:A,0)),"") -> Sudah Foto
A8: 7 | B8: 7 | C8: 20220355 | D8: 0097224224 | E8: Dafa Aulia Ghifaro bin Roby Iskandar | F8: L | G8: 9-A-01 | H8: 221 MD | I8: 9 | J8: Jakarta Timur | K8: =IFERROR(INDEX('Data Real Foto'!B:B,MATCH('Data Foto'!C8,'Data Real Foto'!A:A,0)),"") -> Sudah Foto
A9: 8 | B9: 8 | C9: 20220399 | D9: 0108724665 | E9: Da'i Rijal Rafif bin Saripudin | F9: L | G9: 9-A-01 | H9: 218 MD | I9: 9 | J9: Jakarta Selatan | K9: =IFERROR(INDEX('Data Real Foto'!B:B,MATCH('Data Foto'!C9,'Data Real Foto'!A:A,0)),"") -> Sudah Foto
A10: 9 | B10: 9 | C10: 20220187 | D10: 3102891698 | E10: Derrian Adi Prakoso bin Tedy Setyawan | F10: L | G10: 9-A-01 | H10: 303 MD | I10: 9 | J10: Jakarta Selatan | K10: =IFERROR(INDEX('Data Real Foto'!B:B,MATCH('Data Foto'!C10,'Data Real Foto'!A:A,0)),"") -> Sudah Foto
A11: 10 | B11: 10 | C11: 20220186 | D11: 0107446881 | E11: Fadil Ghany Aswary bin Yulizar Aswari | F11: L | G11: 9-A-01 | H11: 204 MD | I11: 9 | J11: Jakarta Selatan | K11: =IFERROR(INDEX('Data Real Foto'!B:B,MATCH('Data Foto'!C11,'Data Real Foto'!A:A,0)),"") -> Sudah Foto
A12: 11 | B12: 11 | C12: 20220048 | D12: 3101980626 | E12: Fa'iq Atha Nur Hibatullah bin Risun | F12: L | G12: 9-A-01 | H12: 231 MD | I12: 9 | J12: Banten | K12: =IFERROR(INDEX('Data Real Foto'!B:B,MATCH('Data Foto'!C12,'Data Real Foto'!A:A,0)),"") -> Sudah Foto
A13: 12 | B13: 12 | C13: 20220175 | D13: 3097179312 | E13: Fathir Al-Fath bin Usup Suparman | F13: L | G13: 9-A-01 | H13: 203 MD | I13: 9 | J13: Jakarta Barat | K13: =IFERROR(INDEX('Data Real Foto'!B:B,MATCH('Data Foto'!C13,'Data Real Foto'!A:A,0)),"") -> Sudah Foto
... A18: 17 | B18: 17 | C18: 20220127 | D18: 0086647430 | E18: Imam Panji Gumilang bin Nurrohman | F18: L | G18: 9-A-01 | H18: 216 MD | I18: 9 | J18: Jakarta Selatan | K18: =IFERROR(INDEX('Data Real Foto'!B:B,MATCH('Data Foto'!C18,'Data Real Foto'!A:A,0)),"") -> Sudah Foto
A19: 18 | B19: 18 | C19: 20220208 | D19: 0101769788 | E19: Imam Taqi Hady bin Asdi Saputra | F19: L | G19: 9-A-01 | H19: 203 MD | I19: 9 | J19: Jakarta Selatan | K19: =IFERROR(INDEX('Data Real Foto'!B:B,MATCH('Data Foto'!C19,'Data Real Foto'!A:A,0)),"") | L19: Foto buram
A20: 19 | B20: 19 | C20: 20220140 | D20: 3104169306 | E20: Mochamad Ghamel Arrasyiid bin Derit Yanto | F20: L | G20: 9-A-01 | H20: 220 MD | I20: 9 | J20: Jakarta Selatan | K20: =IFERROR(INDEX('Data Real Foto'!B:B,MATCH('Data Foto'!C20,'Data Real Foto'!A:A,0)),"") -> Sudah Foto
A21: 20 | B21: 20 | C21: 20220139 | D21: 3107328494 | E21: Mochamad Ghatan Adlullathiif bin Derit yanto | F21: L | G21: 9-A-01 | H21: 309 MD | I21: 9 | J21: Jakarta Selatan | K21: =IFERROR(INDEX('Data Real Foto'!B:B,MATCH('Data Foto'!C21,'Data Real Foto'!A:A,0)),"") -> Sudah Foto
A22: 21 | B22: 21 | C22: 20220394 | D22: 3102745449 | E22: Mufti Nur Hasbhi bin Eko Wuryanto | F22: L | G22: 9-A-01 | H22: 307 MD | I22: 9 | J22: Jakarta Timur | K22: =IFERROR(INDEX('Data Real Foto'!B:B,MATCH('Data Foto'!C22,'Data Real Foto'!A:A,0)),"") -> Sudah Foto
A23: 22 | B23: 22 | C23: 20220551 | D23: 3099665357 | E23: Muhammad Dzaki As Salam bin Eka Prasetyandani | F23: L | G23: 9-A-01 | H23: 218 MD | I23: 9 | J23: Jawa Timur | K23: =IFERROR(INDEX('Data Real Foto'!B:B,MATCH('Data Foto'!C23,'Data Real Foto'!A:A,0)),"") -> Sudah Foto
A24: 23 | B24: 23 | C24: 20220215 | D24: 3091564028 | E24: Muhammad Ezzequiel Al Fachrezi bin Syarifudin | F24: L | G24: 9-A-01 | H24: 316 MD | I24: 9 | J24: Jakarta Selatan | K24: =IFERROR(INDEX('Data Real Foto'!B:B,MATCH('Data Foto'!C24,'Data Real Foto'!A:A,0)),"") -> Sudah Foto
A25: 24 | B25: 24 | C25: 20220410 | D25: 0097586310 | E25: Muhammad Faris Alghaziy bin Fauzih | F25: L | G25: 9-A-01 | H25: 306 MD | I25: 9 | J25: Jakarta Selatan | K25: =IFERROR(INDEX('Data Real Foto'!B:B,MATCH('Data Foto'!C25,'Data Real Foto'!A:A,0)),"") -> Sudah Foto
A26: 25 | B26: 25 | C26: 20220240 | D26: 0099541486 | E26: Raffa Satria Bintang bin Muhamad Hasani | F26: L | G26: 9-A-01 | H26: 305 MD | I26: 9 | J26: Jakarta Selatan | K26: =IFERROR(INDEX('Data Real Foto'!B:B,MATCH('Data Foto'!C26,'Data Real Foto'!A:A,0)),"") -> Sudah Foto
A27: 26 | B27: 26 | C27: 20220090 | D27: 3098849121 | E27: Rizky Aditya Ramadhan bin Muhammad Idrus | F27: L | G27: 9-A-01 | H27: 308 MD | I27: 9 | J27: Banten | K27: =IFERROR(INDEX('Data Real Foto'!B:B,MATCH('Data Foto'!C27,'Data Real Foto'!A:A,0)),"") -> Sudah Foto
A28: 27 | B28: 27 | C28: 20220001 | D28: 3100612813 | E28: Sabiq Dayyana Ali bin Ali Aminulloh | F28: L | G28: 9-A-01 | H28: 326 MD | I28: 9 | J28: Pusat | K28: =IFERROR(INDEX('Data Real Foto'!B:B,MATCH('Data Foto'!C28,'Data Real Foto'!A:A,0)),"") -> Sudah Foto
A29: 28 | B29: 28 | C29: 20220465 | D29: 0091851108 | E29: Sandya Azri Al Assyada bin Indra Hendrayana | F29: L | G29: 9-A-01 | H29: 204 MD | I29: 9 | J29: Jawa Barat Utara | K29: =IFERROR(INDEX('Data Real Foto'!B:B,MATCH('Data Foto'!C29,'Data Real Foto'!A:A,0)),"") -> Sudah Foto
A30: 29 | B30: 29 | C30: 20220096 | D30: 3091786387 | E30: Shufwan Riza Alfathan bin Shufwan Qudsyi (Alm) | F30: L | G30: 9-A-01 | H30: 232 MD | I30: 9 | J30: Banten | K30: =IFERROR(INDEX('Data Real Foto'!B:B,MATCH('Data Foto'!C30,'Data Real Foto'!A:A,0)),"") -> Sudah Foto
A31: 30 | B31: 30 | C31: 20220326 | D31: 3091753131 | E31: Wildan Al Jabbar bin Udin Wahyudin | F31: L | G31: 9-A-01 | H31: 303 MD | I31: 9 | J31: Jakarta Timur | K31: =IFERROR(INDEX('Data Real Foto'!B:B,MATCH('Data Foto'!C31,'Data Real Foto'!A:A,0)),"") -> Sudah Foto
... A132: 131 | B132: 13 | C132: 20220243 | D132: 3101398543 | E132: Fathu Akbar bin Akmaludin | F132: L | G132: 9-A-05 | H132: 306 MD | I132: 9 | J132: Jakarta Pusat | K132: =IFERROR(INDEX('Data Real Foto'!B:B,MATCH('Data Foto'!C132,'Data Real Foto'!A:A,0)),"") -> Sudah Foto
A133: 132 | B133: 14 | C133: 20220405 | D133: 3108159135 | E133: Fazwa Diva Daulah bin Dede Hendriana | F133: L | G133: 9-A-05 | H133: 214 MD | I133: 9 | J133: Jakarta Timur | K133: =IFERROR(INDEX('Data Real Foto'!B:B,MATCH('Data Foto'!C133,'Data Real Foto'!A:A,0)),"") | L133: sudah keluar
A134: 133 | B134: 15 | C134: 20220209 | D134: 0103206526 | E134: Ghifari Salman Al Rasyid bin Ade Firmansyah | F134: L | G134: 9-A-05 | H134: 220 MD | I134: 9 | J134: Jakarta Selatan | K134: =IFERROR(INDEX('Data Real Foto'!B:B,MATCH('Data Foto'!C134,'Data Real Foto'!A:A,0)),"") -> Sudah Foto
A135: 134 | B135: 16 | C135: 20220163 | D135: 3105734353 | E135: Ibnu Hafidz Al Mu'thi bin Asep Hanhan Burhanudin | F135: L | G135: 9-A-05 | H135: 206 MD | I135: 9 | J135: Jakarta Selatan | K135: =IFERROR(INDEX('Data Real Foto'!B:B,MATCH('Data Foto'!C135,'Data Real Foto'!A:A,0)),"") -> Sudah Foto
A136: 135 | B136: 17 | C136: 20220452 | D136: 0103098731 | E136: Idham Chalid Qohar bin Suhardiyat | F136: L | G136: 9-A-05 | H136: 201 MD | I136: 9 | J136: Jawa Barat Utara | K136: =IFERROR(INDEX('Data Real Foto'!B:B,MATCH('Data Foto'!C136,'Data Real Foto'!A:A,0)),"") -> Sudah Foto
A137: 136 | B137: 18 | C137: 20220523 | D137: 0102364660 | E137: Muhamad Ilhamsyah bin Sujana | F137: L | G137: 9-A-05 | H137: 219 MD | I137: 9 | J137: Jawa Barat Selatan | K137: =IFERROR(INDEX('Data Real Foto'!B:B,MATCH('Data Foto'!C137,'Data Real Foto'!A:A,0)),"") -> Sudah Foto
A138: 137 | B138: 19 | C138: 20220490 | D138: 0099078727 | E138: Muhamad Ilyas bin Komar | F138: L | G138: 9-A-05 | H138: 205 MD | I138: 9 | J138: Jawa Barat Selatan | K138: =IFERROR(INDEX('Data Real Foto'!B:B,MATCH('Data Foto'!C138,'Data Real Foto'!A:A,0)),"") -> Sudah Foto
A139: 138 | B139: 20 | C139: 20220123 | D139: 3108188922 | E139: Muhammad Naufal Rizqullah bin Dodi Darmawan | F139: L | G139: 9-A-05 | H139: 319 MD | I139: 9 | J139: Jakarta Selatan | K139: =IFERROR(INDEX('Data Real Foto'!B:B,MATCH('Data Foto'!C139,'Data Real Foto'!A:A,0)),"") -> Sudah Foto
A140: 139 | B140: 21 | C140: 20220261 | D140: 0105456302 | E140: Muhammad Nazir bin Ahmad Suandi | F140: L | G140: 9-A-05 | H140: 331 MD | I140: 9 | J140: Jakarta Pusat | K140: =IFERROR(INDEX('Data Real Foto'!B:B,MATCH('Data Foto'!C140,'Data Real Foto'!A:A,0)),"") -> Sudah Foto
A141: 140 | B141: 22 | C141: 20220256 | D141: 3093543711 | E141: Naufal Mufidi Dzakwan bin Dimas Harisetiagara | F141: L | G141: 9-A-05 | H141: 220 MD | I141: 9 | J141: Jakarta Selatan | K141: =IFERROR(INDEX('Data Real Foto'!B:B,MATCH('Data Foto'!C141,'Data Real Foto'!A:A,0)),"") -> Sudah Foto
A142: 141 | B142: 23 | C142: 20220169 | D142: 3107320784 | E142: Rafli Akbar bin Mazwandi | F142: L | G142: 9-A-05 | H142: 228 MD | I142: 9 | J142: Jakarta Barat | K142: =IFERROR(INDEX('Data Real Foto'!B:B,MATCH('Data Foto'!C142,'Data Real Foto'!A:A,0)),"") -> Sudah Foto
A143: 142 | B143: 24 | C143: 20220302 | D143: 0094533545 | E143: Rahlil Dzihni Adam bin Zahiri Adi Gunawan | F143: L | G143: 9-A-05 | H143: 314 MD | I143: 9 | J143: Jakarta Timur | K143: =IFERROR(INDEX('Data Real Foto'!B:B,MATCH('Data Foto'!C143,'Data Real Foto'!A:A,0)),"") -> Sudah Foto
A144: 143 | B144: 25 | C144: 20220360 | D144: 0101340829 | E144: Reza Syah Alam bin Muhaimin | F144: L | G144: 9-A-05 | H144: 322 MD | I144: 9 | J144: Jakarta Timur | K144: =IFERROR(INDEX('Data Real Foto'!B:B,MATCH('Data Foto'!C144,'Data Real Foto'!A:A,0)),"") -> Sudah Foto
...

Sheet Data Real Foto
A1: No Induk | B1: Keterangan
A2: 20220001 | B2: Sudah Foto
A3: 20220002 | B3: Sudah Foto
A4: 20220003 | B4: Sudah Foto
A5: 20220004 | B5: Sudah Foto
A6: 20220005 | B6: Sudah Foto
A7: 20220006 | B7: Sudah Foto
A8: 20220007 | B8: Sudah Foto
A9: 20220008 | B9: Sudah Foto
A10: 20220009 | B10: Sudah Foto
A11: 20220010 | B11: Sudah Foto
A12: 20220011 | B12: Sudah Foto
A13: 20220012 | B13: Sudah Foto
... A550: 20220595 | B550: Sudah Foto
